Workbook

Sheet README
A1: Group | B1: Tab / Surface | C1: What it does | D1: Edit Rule | E1: Link
A2: READ | B2: README | C2: Start here. This tab explains the workbook structure, the tab colors, and the role of each working surface. | D2: Do not edit manually.
A3: READ | B3: Blue tabs | C3: Reference and orientation tabs that explain the system or link out to other surfaces. | D3: Read only.
A4: INTERACTIVE | B4: Green tabs | C4: Editorial tabs where humans can review, plan, or stage changes. | D4: Edit only the intended working cells.
A5: DATA | B5: Orange tabs | C5: Generated tabs fed by toolkit exports, bundle state, or procedural snapshots. | D5: Do not edit manually. Regenerate from the toolkit.
A7: INTERACTIVE | B7: All Progressions | C7: Main editorial review view for level order, screenshots, feedback, and playtest notes. | D7: Edit only the review columns such as Need fixes, Feedback, Feedback Owner, and Playtest difficulty.
A8: INTERACTIVE | B8: Mix Planner | C8: Plan and approve Live Ops Mixes before materialization. | D8: Edit proposal, approval, slot, tutorial, and notes fields only.
A9: INTERACTIVE | B9: Level Renames | C9: Stage level renames before applying them locally. | D9: Edit Target Name and Notes, then run the rename action.
A10: DATA | B10: Level Catalog | C10: Canonical level catalog generated from bundle state. | D10: Do not edit manually.
A11: DATA | B11: Level Manager state | C11: Machine-generated sync surface used by toolkit and export flows. | D11: Do not edit manually.
A12: DATA | B12: Procedural learning | C12: Snapshot of approved and rejected procedural feedback for review and reporting. | D12: Do not edit manually.
A14: ACTION | B14: Open Web Toolkit | C14: Open the local toolkit UI. | D14: Runs on the local server. | E14: http://127.0.0.1:8080/
A15: ACTION | B15: Sync Spreadsheet | C15: Rebuild the canonical workbook and payload, then push the live Google Sheet. | D15: Runs on the local server. | E15: http://127.0.0.1:8080/api/action/sync-spreadsheet
A16: ACTION | B16: Regenerate Payload | C16: Rebuild the canonical workbook and payload locally without a live push. | D16: Runs on the local server. | E16: http://127.0.0.1:8080/api/action/generate-payload
A17: ACTION | B17: Apply Level Renames | C17: Apply staged rename rows back to the canonical repo files. | D17: Runs on the local server. | E17: http://127.0.0.1:8080/api/action/apply-level-renames
A18: ACTION | B18: Materialize Mixes | C18: Export approved Live Ops Mixes into bundle output. | D18: Runs on the local server. | E18: http://127.0.0.1:8080/api/action/materialize-mixes
A19: ACTION | B19: Validate All Levels | C19: Run the current all-level validation action. | D19: Runs on the local server. | E19: http://127.0.0.1:8080/api/action/validate-levels
A20: ACTION | B20: Backup Progressions | C20: Create a local progression backup before major changes. | D20: Runs on the local server. | E20: http://127.0.0.1:8080/api/action/backup-progressions
A22: READ | B22: Game URL | C22: Playable build reference. | D22: Reference only. | E22: https://king-ccss-minigame-hungrybears.firebaseapp.com/
A23: READ | B23: Team board | C23: Shared board for wider team context. | D23: Reference only. | E23: https://miro.com/app/board/uXjVJTMkKXk=/
A25: CONSTRAINT | B25: Grid Size Limit | C25: Max board size is 7 rows × 8 cols (56 cells). Levels exceeding this are flagged as OVERSIZED in Level Catalog and Level Manager state. Added 2026-03-28. | D25: Do not create levels larger than 7×8.
A26: TOOL | B26: Level Editor | C26: Web-based level editor (level-editor.html) with enforced 7×8 max grid. Supports pairs, blockers, bear placement, JSON export/import. | D26: Open in browser. Edit and export.

Sheet All Progressions
A1: Position in Progression | B1: Level ID | C1: Name/Title | D1: Progression | E1: Difficulty | F1: Screenshot | G1: Code File | H1: Need tweak | I1: Need fixes | J1: Feedback | K1: Feedback Owner | L1: Playtest difficulty | M1: Notes
A2: 0 | B2: 001 | C2: 00 · tutorial | D2: Progression A | E2: Easy | G2: tutorial_level.json | H2: yes | I2: FALSE | M2: Tutorial slot
A3: 1 | B3: 002 | C3: 01 · progression1 level1 | D3: Progression A | E3: Easy | G3: progression1_level1.json | H3: yes | I3: FALSE
A4: 2 | B4: 003 | C4: 02 · progresion1 level2 | D4: Progression A | E4: Easy | G4: progresion1_level2.json | H4: yes | I4: FALSE
A5: 3 | B5: 004 | C5: 03 · progression1 level3 | D5: Progression A | E5: Medium | G5: progression1_level3.json | H5: yes | I5: FALSE
A6: 4 | B6: 005 | C6: 04 · progression1 level4 | D6: Progression A | E6: Easy | G6: progression1_level4.json | H6: yes | I6: FALSE
A7: 5 | B7: 006 | C7: 05 · progression1 level5 | D7: Progression A | E7: Easy | G7: progression1_level5.json | H7: yes | I7: FALSE
A8: 6 | B8: 007 | C8: 06 · progresion1 level6 | D8: Progression A | E8: Medium | G8: progresion1_level6.json | H8: yes | I8: FALSE
A9: 7 | B9: 008 | C9: 07 · progression1 level7 v2 | D9: Progression A | E9: Hard | G9: progression1_level7_v2.json | H9: yes | I9: FALSE
A10: 8 | B10: 009 | C10: 08 · progression1 level8 | D10: Progression A | E10: Easy | G10: progression1_level8.json | H10: yes | I10: FALSE
A11: 9 | B11: 010 | C11: 09 · progression1 level9 | D11: Progression A | E11: Medium | G11: progression1_level9.json | H11: yes | I11: FALSE
A12: 10 | B12: 011 | C12: 10 · progression1 level10 | D12: Progression A | E12: Hard | G12: progression1_level10.json | H12: yes | I12: FALSE
A13: 0 | B13: 012 | C13: 00 · tutorial | D13: Progression B | E13: Easy | G13: tutorial_level.json | H13: yes | I13: FALSE | M13: Tutorial slot
A14: 1 | B14: 013 | C14: 01 · progresion2 level1 | D14: Progression B | E14: Easy | G14: progresion2_level1.json | H14: yes | I14: FALSE
A15: 2 | B15: 014 | C15: 02 · progresion2 level2 | D15: Progression B | E15: Easy | G15: progresion2_level2.json | H15: yes | I15: FALSE
A16: 3 | B16: 015 | C16: 03 · progresion2 level3 | D16: Progression B | E16: Medium | G16: progresion2_level3.json | H16: yes | I16: FALSE
A17: 4 | B17: 016 | C17: 04 · progresion2 level4 | D17: Progression B | E17: Hard | G17: progresion2_level4.json | H17: yes | I17: FALSE
A18: 5 | B18: 017 | C18: 05 · progresion2 level5 | D18: Progression B | E18: Easy | G18: progresion2_level5.json | H18: yes | I18: FALSE
A19: 6 | B19: 018 | C19: 06 · progresion2 level6 | D19: Progression B | E19: Medium | G19: progresion2_level6.json | H19: yes | I19: FALSE
A20: 7 | B20: 019 | C20: 07 · progresion2 level7 | D20: Progression B | E20: Hard | G20: progresion2_level7.json | H20: yes | I20: FALSE
A21: 8 | B21: 020 | C21: 08 · progresion2 level8 | D21: Progression B | E21: Easy | G21: progresion2_level8.json | H21: yes | I21: FALSE
A22: 9 | B22: 021 | C22: 09 · progresion2 level9 | D22: Progression B | E22: Medium | G22: progresion2_level9.json | H22: yes | I22: FALSE
A23: 10 | B23: 022 | C23: 10 · progresion2 level10 | D23: Progression B | E23: Hard | G23: progresion2_level10.json | H23: yes | I23: FALSE
A24: 0 | B24: 023 | C24: 00 · tutorial | D24: Progression C | E24: Easy | G24: tutorial_level.json | H24: yes | I24: FALSE | M24: Tutorial slot
A25: 1 | B25: 024 | C25: 01 · progression3 level1 v2 | D25: Progression C | E25: Easy | G25: progression3_level1_v2.json | H25: yes | I25: FALSE
A26: 2 | B26: 025 | C26: 02 · progression 3 level 2 v2 | D26: Progression C | E26: Easy | G26: progression_3_level_2_v2.json | H26: yes | I26: FALSE
A27: 3 | B27: 026 | C27: 03 · progression 3 level3 | D27: Progression C | E27: Medium | G27: progression_3_level3.json | H27: yes | I27: FALSE
A28: 4 | B28: 027 | C28: 04 · progression 3 level4 | D28: Progression C | E28: Easy | G28: progression_3_level4.json | H28: yes | I28: FALSE
A29: 5 | B29: 028 | C29: 05 · progression 3 level5 | D29: Progression C | E29: Medium | G29: progression_3_level5.json | H29: yes | I29: FALSE
A30: 6 | B30: 029 | C30: 06 · progression 3 level6 | D30: Progression C | E30: Easy | G30: progression_3_level6.json | H30: yes | I30: FALSE
A31: 7 | B31: 030 | C31: 07 · progression 3 level7 v2 | D31: Progression C | E31: Medium | G31: progression_3_level7_v2.json | H31: yes | I31: FALSE
A32: 8 | B32: 031 | C32: 08 · progression 3 level 8 v2 | D32: Progression C | E32: Easy | G32: progression_3_level_8_v2.json | H32: yes | I32: FALSE
A33: 9 | B33: 032 | C33: 09 · progression 3 level9 v2 | D33: Progression C | E33: Medium | G33: progression_3_level9_v2.json | H33: yes | I33: FALSE
A34: 10 | B34: 033 | C34: 10 · progression 3 level10 v2 | D34: Progression C | E34: Hard | G34: progression_3_level10_v2.json | H34: yes | I34: FALSE
A35: 0 | B35: 034 | C35: 00 · tutorial | D35: Procedural 1 | E35: Easy | G35: tutorial_level.json | H35: yes | I35: FALSE | M35: Tutorial slot
A36: 1 | B36: 035 | C36: 01 · slot2 1 | D36: Procedural 1 | E36: Easy | G36: slot2_1.json | H36: yes | I36: FALSE
A37: 2 | B37: 036 | C37: 02 · slot2 2 | D37: Procedural 1 | E37: Hard | G37: slot2_2.json | H37: yes | I37: FALSE
A38: 3 | B38: 037 | C38: 03 · slot2 3 | D38: Procedural 1 | E38: Hard | G38: slot2_3.json | H38: yes | I38: FALSE
A39: 4 | B39: 038 | C39: 04 · slot2 4 | D39: Procedural 1 | E39: Hard | G39: slot2_4.json | H39: yes | I39: FALSE
A40: 5 | B40: 039 | C40: 05 · procedular reference large 005 | D40: Procedural 1 | E40: Hard | G40: procedular_reference_large_005.json | H40: yes | I40: FALSE
...

Sheet Mix Planner
A1: Proposal ID | B1: Folder Name | C1: Approved | D1: Materialized | E1: Source Progression | F1: Suggestion | G1: Tutorial File | H1: Slot 1 | I1: Slot 2 | J1: Slot 3 | K1: Slot 4 | L1: Slot 5 | M1: Slot 6 | N1: Slot 7 | O1: Slot 8 | P1: Slot 9 | Q1: Slot 10 | R1: Curve | S1: Notes | T1: Output Folder
A2: original_a_current | B2: original_progression_a_current | C2: FALSE | D2: FALSE | E2: Original Progression A | F2: Original Order | G2: tutorial_level.json | H2: progression1_level1.json | I2: progresion1_level2.json | J2: progression1_level3.json | K2: progression1_level4.json | L2: progression1_level5.json | M2: progresion1_level6.json | N2: progression1_level7_v2.json | O2: progression1_level8.json | P2: progression1_level9.json | Q2: progression1_level10.json | R2: =SPARKLINE({IFERROR(VLOOKUP(H2,'Level Catalog'!A:E,5,FALSE),0),IFERROR(VLOOKUP(I2,'Level Catalog'!A:E,5,FALSE),0),IFERROR(VLOOKUP(J2,'Level Catalog'!A:E,5,FALSE),0),IFERROR(VLOOKUP(K2,'Level Catalog'!A:E,5,FALSE),0),IFERROR(VLOOKUP(L2,'Level Catalog'!A:E,5,FALSE),0),IFERROR(VLOOKUP(M2,'Level Catalog'!A:E,5,FALSE),0),IFERROR(VLOOKUP(N2,'Level Catalog'!A:E,5,FALSE),0),IFERROR(VLOOKUP(O2,'Level Catalog'!A:E,5,FALSE),0),IFERROR(VLOOKUP(P2,'Level Catalog'!A:E,5,FALSE),0),IFERROR(VLOOKUP(Q2,'Level Catalog'!A:E,5,FALSE),0)},{"charttype","line";"linewidth",2;"empty","zero"})
F3: Screens | G3: lvl_109_tutorial_level.png | H3: progression1_level1.png | I3: progresion1_level2.png | J3: progression1_level3.png | K3: progression1_level4.png | L3: progression1_level5.png | M3: progresion1_level6.png | N3: progression1_level7_v2.png | O3: progression1_level8.png | P3: progression1_level9.png | Q3: progression1_level10.png
F4: Difficulty | G4: Easy | H4: Easy | I4: Easy | J4: Medium | K4: Easy | L4: Easy | M4: Medium | N4: Hard | O4: Easy | P4: Medium | Q4: Hard
A5: original_a_rotate_1 | B5: original_progression_a_rotate_1 | C5: FALSE | D5: FALSE | E5: Original Progression A | F5: Rotate +1 | G5: tutorial_level.json | H5: progresion1_level2.json | I5: progression1_level3.json | J5: progression1_level4.json | K5: progression1_level5.json | L5: progresion1_level6.json | M5: progression1_level7_v2.json | N5: progression1_level8.json | O5: progression1_level9.json | P5: progression1_level10.json | Q5: progression1_level1.json | R5: =SPARKLINE({IFERROR(VLOOKUP(H5,'Level Catalog'!A:E,5,FALSE),0),IFERROR(VLOOKUP(I5,'Level Catalog'!A:E,5,FALSE),0),IFERROR(VLOOKUP(J5,'Level Catalog'!A:E,5,FALSE),0),IFERROR(VLOOKUP(K5,'Level Catalog'!A:E,5,FALSE),0),IFERROR(VLOOKUP(L5,'Level Catalog'!A:E,5,FALSE),0),IFERROR(VLOOKUP(M5,'Level Catalog'!A:E,5,FALSE),0),IFERROR(VLOOKUP(N5,'Level Catalog'!A:E,5,FALSE),0),IFERROR(VLOOKUP(O5,'Level Catalog'!A:E,5,FALSE),0),IFERROR(VLOOKUP(P5,'Level Catalog'!A:E,5,FALSE),0),IFERROR(VLOOKUP(Q5,'Level Catalog'!A:E,5,FALSE),0)},{"charttype","line";"linewidth",2;"empty","zero"})
F6: Screens | G6: lvl_109_tutorial_level.png | H6: progresion1_level2.png | I6: progression1_level3.png | J6: progression1_level4.png | K6: progression1_level5.png | L6: progresion1_level6.png | M6: progression1_level7_v2.png | N6: progression1_level8.png | O6: progression1_level9.png | P6: progression1_level10.png | Q6: progression1_level1.png
F7: Difficulty | G7: Easy | H7: Easy | I7: Medium | J7: Easy | K7: Easy | L7: Medium | M7: Hard | N7: Easy | O7: Medium | P7: Hard | Q7: Easy
A8: original_b_current | B8: original_progression_b_current | C8: FALSE | D8: FALSE | E8: Original Progression B | F8: Original Order | G8: tutorial_level.json | H8: progresion2_level1.json | I8: progresion2_level2.json | J8: progresion2_level3.json | K8: progresion2_level4.json | L8: progresion2_level5.json | M8: progresion2_level6.json | N8: progresion2_level7.json | O8: progresion2_level8.json | P8: progresion2_level9.json | Q8: progresion2_level10.json | R8: =SPARKLINE({IFERROR(VLOOKUP(H8,'Level Catalog'!A:E,5,FALSE),0),IFERROR(VLOOKUP(I8,'Level Catalog'!A:E,5,FALSE),0),IFERROR(VLOOKUP(J8,'Level Catalog'!A:E,5,FALSE),0),IFERROR(VLOOKUP(K8,'Level Catalog'!A:E,5,FALSE),0),IFERROR(VLOOKUP(L8,'Level Catalog'!A:E,5,FALSE),0),IFERROR(VLOOKUP(M8,'Level Catalog'!A:E,5,FALSE),0),IFERROR(VLOOKUP(N8,'Level Catalog'!A:E,5,FALSE),0),IFERROR(VLOOKUP(O8,'Level Catalog'!A:E,5,FALSE),0),IFERROR(VLOOKUP(P8,'Level Catalog'!A:E,5,FALSE),0),IFERROR(VLOOKUP(Q8,'Level Catalog'!A:E,5,FALSE),0)},{"charttype","line";"linewidth",2;"empty","zero"})
F9: Screens | G9: lvl_109_tutorial_level.png | H9: progresion2_level1.png | I9: progresion2_level2.png | J9: progresion2_level3.png | K9: progresion2_level4.png | L9: progresion2_level5.png | M9: progresion2_level6.png | N9: progresion2_level7.png | O9: progresion2_level8.png | P9: progresion2_level9.png | Q9: progresion2_level10.png
F10: Difficulty | G10: Easy | H10: Easy | I10: Easy | J10: Medium | K10: Hard | L10: Easy | M10: Medium | N10: Hard | O10: Easy | P10: Medium | Q10: Hard
A11: original_b_rotate_1 | B11: original_progression_b_rotate_1 | C11: FALSE | D11: FALSE | E11: Original Progression B | F11: Rotate +1 | G11: tutorial_level.json | H11: progresion2_level2.json | I11: progresion2_level3.json | J11: progresion2_level4.json | K11: progresion2_level5.json | L11: progresion2_level6.json | M11: progresion2_level7.json | N11: progresion2_level8.json | O11: progresion2_level9.json | P11: progresion2_level10.json | Q11: progresion2_level1.json | R11: =SPARKLINE({IFERROR(VLOOKUP(H11,'Level Catalog'!A:E,5,FALSE),0),IFERROR(VLOOKUP(I11,'Level Catalog'!A:E,5,FALSE),0),IFERROR(VLOOKUP(J11,'Level Catalog'!A:E,5,FALSE),0),IFERROR(VLOOKUP(K11,'Level Catalog'!A:E,5,FALSE),0),IFERROR(VLOOKUP(L11,'Level Catalog'!A:E,5,FALSE),0),IFERROR(VLOOKUP(M11,'Level Catalog'!A:E,5,FALSE),0),IFERROR(VLOOKUP(N11,'Level Catalog'!A:E,5,FALSE),0),IFERROR(VLOOKUP(O11,'Level Catalog'!A:E,5,FALSE),0),IFERROR(VLOOKUP(P11,'Level Catalog'!A:E,5,FALSE),0),IFERROR(VLOOKUP(Q11,'Level Catalog'!A:E,5,FALSE),0)},{"charttype","line";"linewidth",2;"empty","zero"})
F12: Screens | G12: lvl_109_tutorial_level.png | H12: progresion2_level2.png | I12: progresion2_level3.png | J12: progresion2_level4.png | K12: progresion2_level5.png | L12: progresion2_level6.png | M12: progresion2_level7.png | N12: progresion2_level8.png | O12: progresion2_level9.png | P12: progresion2_level10.png | Q12: progresion2_level1.png
F13: Difficulty | G13: Easy | H13: Easy | I13: Medium | J13: Hard | K13: Easy | L13: Medium | M13: Hard | N13: Easy | O13: Medium | P13: Hard | Q13: Easy
A14: original_c_current | B14: original_progression_c_current | C14: FALSE | D14: FALSE | E14: Original Progression C | F14: Original Order | G14: tutorial_level.json | H14: progression3_level1_v2.json | I14: progression_3_level_2_v2.json | J14: progression_3_level3.json | K14: progression_3_level4.json | L14: progression_3_level5.json | M14: progression_3_level6.json | N14: progression_3_level7_v2.json | O14: progression_3_level_8_v2.json | P14: progression_3_level9_v2.json | Q14: progression_3_level10_v2.json | R14: =SPARKLINE({IFERROR(VLOOKUP(H14,'Level Catalog'!A:E,5,FALSE),0),IFERROR(VLOOKUP(I14,'Level Catalog'!A:E,5,FALSE),0),IFERROR(VLOOKUP(J14,'Level Catalog'!A:E,5,FALSE),0),IFERROR(VLOOKUP(K14,'Level Catalog'!A:E,5,FALSE),0),IFERROR(VLOOKUP(L14,'Level Catalog'!A:E,5,FALSE),0),IFERROR(VLOOKUP(M14,'Level Catalog'!A:E,5,FALSE),0),IFERROR(VLOOKUP(N14,'Level Catalog'!A:E,5,FALSE),0),IFERROR(VLOOKUP(O14,'Level Catalog'!A:E,5,FALSE),0),IFERROR(VLOOKUP(P14,'Level Catalog'!A:E,5,FALSE),0),IFERROR(VLOOKUP(Q14,'Level Catalog'!A:E,5,FALSE),0)},{"charttype","line";"linewidth",2;"empty","zero"})
F15: Screens | G15: lvl_109_tutorial_level.png | H15: progression3_level1_v2.png | I15: progression_3_level_2_v2.png | J15: progression_3_level3.png | K15: progression_3_level4.png | L15: progression_3_level5.png | M15: progression_3_level6.png | N15: progression_3_level7_v2.png | O15: progression_3_level_8_v2.png | P15: progression_3_level9_v2.png | Q15: progression_3_level10_v2.png
F16: Difficulty | G16: Easy | H16: Easy | I16: Easy | J16: Medium | K16: Easy | L16: Medium | M16: Easy | N16: Medium | O16: Easy | P16: Medium | Q16: Hard
A17: original_c_rotate_1 | B17: original_progression_c_rotate_1 | C17: FALSE | D17: FALSE | E17: Original Progression C | F17: Rotate +1 | G17: tutorial_level.json | H17: progression_3_level_2_v2.json | I17: progression_3_level3.json | J17: progression_3_level4.json | K17: progression_3_level5.json | L17: progression_3_level6.json | M17: progression_3_level7_v2.json | N17: progression_3_level_8_v2.json | O17: progression_3_level9_v2.json | P17: progression_3_level10_v2.json | Q17: progression3_level1_v2.json | R17: =SPARKLINE({IFERROR(VLOOKUP(H17,'Level Catalog'!A:E,5,FALSE),0),IFERROR(VLOOKUP(I17,'Level Catalog'!A:E,5,FALSE),0),IFERROR(VLOOKUP(J17,'Level Catalog'!A:E,5,FALSE),0),IFERROR(VLOOKUP(K17,'Level Catalog'!A:E,5,FALSE),0),IFERROR(VLOOKUP(L17,'Level Catalog'!A:E,5,FALSE),0),IFERROR(VLOOKUP(M17,'Level Catalog'!A:E,5,FALSE),0),IFERROR(VLOOKUP(N17,'Level Catalog'!A:E,5,FALSE),0),IFERROR(VLOOKUP(O17,'Level Catalog'!A:E,5,FALSE),0),IFERROR(VLOOKUP(P17,'Level Catalog'!A:E,5,FALSE),0),IFERROR(VLOOKUP(Q17,'Level Catalog'!A:E,5,FALSE),0)},{"charttype","line";"linewidth",2;"empty","zero"})
F18: Screens | G18: lvl_109_tutorial_level.png | H18: progression_3_level_2_v2.png | I18: progression_3_level3.png | J18: progression_3_level4.png | K18: progression_3_level5.png | L18: progression_3_level6.png | M18: progression_3_level7_v2.png | N18: progression_3_level_8_v2.png | O18: progression_3_level9_v2.png | P18: progression_3_level10_v2.png | Q18: progression3_level1_v2.png
F19: Difficulty | G19: Easy | H19: Easy | I19: Medium | J19: Easy | K19: Medium | L19: Easy | M19: Medium | N19: Easy | O19: Medium | P19: Hard | Q19: Easy
A20: original_1_current | B20: original_progression_1_current | C20: FALSE | D20: FALSE | E20: Original Progression 1 | F20: Original Order | G20: tutorial_level.json | H20: slot2_1.json | I20: slot2_2.json | J20: slot2_3.json | K20: slot2_4.json | L20: procedular_reference_large_005.json | M20: procedular_reference_large_006.json | N20: procedular_reference_large_007.json | O20: procedular_reference_large_008.json | P20: procedular_reference_large_009.json | Q20: procedular_reference_large_010.json | R20: =SPARKLINE({IFERROR(VLOOKUP(H20,'Level Catalog'!A:E,5,FALSE),0),IFERROR(VLOOKUP(I20,'Level Catalog'!A:E,5,FALSE),0),IFERROR(VLOOKUP(J20,'Level Catalog'!A:E,5,FALSE),0),IFERROR(VLOOKUP(K20,'Level Catalog'!A:E,5,FALSE),0),IFERROR(VLOOKUP(L20,'Level Catalog'!A:E,5,FALSE),0),IFERROR(VLOOKUP(M20,'Level Catalog'!A:E,5,FALSE),0),IFERROR(VLOOKUP(N20,'Level Catalog'!A:E,5,FALSE),0),IFERROR(VLOOKUP(O20,'Level Catalog'!A:E,5,FALSE),0),IFERROR(VLOOKUP(P20,'Level Catalog'!A:E,5,FALSE),0),IFERROR(VLOOKUP(Q20,'Level Catalog'!A:E,5,FALSE),0)},{"charttype","line";"linewidth",2;"empty","zero"})
F21: Screens | G21: lvl_109_tutorial_level.png | H21: slot2_1.png | I21: slot2_2.png | J21: slot2_3.png | K21: slot2_4.png | L21: procedular_reference_large_005.png | M21: procedular_reference_large_006.png | N21: procedular_reference_large_007.png | O21: procedular_reference_large_008.png | P21: procedular_reference_large_009.png | Q21: procedular_reference_large_010.png
F22: Difficulty | G22: Easy | H22: Easy | I22: Hard | J22: Hard | K22: Hard | L22: Hard | M22: Hard | N22: Hard | O22: Hard | P22: Hard | Q22: Hard
A23: original_1_rotate_1 | B23: original_progression_1_rotate_1 | C23: FALSE | D23: FALSE | E23: Original Progression 1 | F23: Rotate +1 | G23: tutorial_level.json | H23: slot2_2.json | I23: slot2_3.json | J23: slot2_4.json | K23: procedular_reference_large_005.json | L23: procedular_reference_large_006.json | M23: procedular_reference_large_007.json | N23: procedular_reference_large_008.json | O23: procedular_reference_large_009.json | P23: procedular_reference_large_010.json | Q23: slot2_1.json | R23: =SPARKLINE({IFERROR(VLOOKUP(H23,'Level Catalog'!A:E,5,FALSE),0),IFERROR(VLOOKUP(I23,'Level Catalog'!A:E,5,FALSE),0),IFERROR(VLOOKUP(J23,'Level Catalog'!A:E,5,FALSE),0),IFERROR(VLOOKUP(K23,'Level Catalog'!A:E,5,FALSE),0),IFERROR(VLOOKUP(L23,'Level Catalog'!A:E,5,FALSE),0),IFERROR(VLOOKUP(M23,'Level Catalog'!A:E,5,FALSE),0),IFERROR(VLOOKUP(N23,'Level Catalog'!A:E,5,FALSE),0),IFERROR(VLOOKUP(O23,'Level Catalog'!A:E,5,FALSE),0),IFERROR(VLOOKUP(P23,'Level Catalog'!A:E,5,FALSE),0),IFERROR(VLOOKUP(Q23,'Level Catalog'!A:E,5,FALSE),0)},{"charttype","line";"linewidth",2;"empty","zero"})
F24: Screens | G24: lvl_109_tutorial_level.png | H24: slot2_2.png | I24: slot2_3.png | J24: slot2_4.png | K24: procedular_reference_large_005.png | L24: procedular_reference_large_006.png | M24: procedular_reference_large_007.png | N24: procedular_reference_large_008.png | O24: procedular_reference_large_009.png | P24: procedular_reference_large_010.png | Q24: slot2_1.png
F25: Difficulty | G25: Easy | H25: Hard | I25: Hard | J25: Hard | K25: Hard | L25: Hard | M25: Hard | N25: Hard | O25: Hard | P25: Hard | Q25: Easy
A26: original_2_current | B26: original_progression_2_current | C26: FALSE | D26: FALSE | E26: Original Progression 2 | F26: Original Order | G26: tutorial_level.json | H26: procedular_reference_large_011.json | I26: procedular_reference_large_012.json | J26: procedular_reference_large_013.json | K26: procedular_reference_large_014.json | L26: procedular_reference_large_015.json | M26: procedular_reference_large_016.json | N26: procedular_reference_large_017.json | O26: procedular_reference_large_018.json | P26: procedular_reference_large_019.json | Q26: procedular_reference_large_020.json | R26: =SPARKLINE({IFERROR(VLOOKUP(H26,'Level Catalog'!A:E,5,FALSE),0),IFERROR(VLOOKUP(I26,'Level Catalog'!A:E,5,FALSE),0),IFERROR(VLOOKUP(J26,'Level Catalog'!A:E,5,FALSE),0),IFERROR(VLOOKUP(K26,'Level Catalog'!A:E,5,FALSE),0),IFERROR(VLOOKUP(L26,'Level Catalog'!A:E,5,FALSE),0),IFERROR(VLOOKUP(M26,'Level Catalog'!A:E,5,FALSE),0),IFERROR(VLOOKUP(N26,'Level Catalog'!A:E,5,FALSE),0),IFERROR(VLOOKUP(O26,'Level Catalog'!A:E,5,FALSE),0),IFERROR(VLOOKUP(P26,'Level Catalog'!A:E,5,FALSE),0),IFERROR(VLOOKUP(Q26,'Level Catalog'!A:E,5,FALSE),0)},{"charttype","line";"linewidth",2;"empty","zero"})
F27: Screens | G27: lvl_109_tutorial_level.png | H27: procedular_reference_large_011.png | I27: procedular_reference_large_012.png | J27: procedular_reference_large_013.png | K27: procedular_reference_large_014.png | L27: procedular_reference_large_015.png | M27: procedular_reference_large_016.png | N27: procedular_reference_large_017.png | O27: procedular_reference_large_018.png | P27: procedular_reference_large_019.png | Q27: procedular_reference_large_020.png
F28: Difficulty | G28: Easy | H28: Hard | I28: Hard | J28: Hard | K28: Hard | L28: Hard | M28: Hard | N28: Hard | O28: Hard | P28: Hard | Q28: Hard
A29: original_2_rotate_1 | B29: original_progression_2_rotate_1 | C29: FALSE | D29: FALSE | E29: Original Progression 2 | F29: Rotate +1 | G29: tutorial_level.json | H29: procedular_reference_large_012.json | I29: procedular_reference_large_013.json | J29: procedular_reference_large_014.json | K29: procedular_reference_large_015.json | L29: procedular_reference_large_016.json | M29: procedular_reference_large_017.json | N29: procedular_reference_large_018.json | O29: procedular_reference_large_019.json | P29: procedular_reference_large_020.json | Q29: procedular_reference_large_011.json | R29: =SPARKLINE({IFERROR(VLOOKUP(H29,'Level Catalog'!A:E,5,FALSE),0),IFERROR(VLOOKUP(I29,'Level Catalog'!A:E,5,FALSE),0),IFERROR(VLOOKUP(J29,'Level Catalog'!A:E,5,FALSE),0),IFERROR(VLOOKUP(K29,'Level Catalog'!A:E,5,FALSE),0),IFERROR(VLOOKUP(L29,'Level Catalog'!A:E,5,FALSE),0),IFERROR(VLOOKUP(M29,'Level Catalog'!A:E,5,FALSE),0),IFERROR(VLOOKUP(N29,'Level Catalog'!A:E,5,FALSE),0),IFERROR(VLOOKUP(O29,'Level Catalog'!A:E,5,FALSE),0),IFERROR(VLOOKUP(P29,'Level Catalog'!A:E,5,FALSE),0),IFERROR(VLOOKUP(Q29,'Level Catalog'!A:E,5,FALSE),0)},{"charttype","line";"linewidth",2;"empty","zero"})
F30: Screens | G30: lvl_109_tutorial_level.png | H30: procedular_reference_large_012.png | I30: procedular_reference_large_013.png | J30: procedular_reference_large_014.png | K30: procedular_reference_large_015.png | L30: procedular_reference_large_016.png | M30: procedular_reference_large_017.png | N30: procedular_reference_large_018.png | O30: procedular_reference_large_019.png | P30: procedular_reference_large_020.png | Q30: procedular_reference_large_011.png
F31: Difficulty | G31: Easy | H31: Hard | I31: Hard | J31: Hard | K31: Hard | L31: Hard | M31: Hard | N31: Hard | O31: Hard | P31: Hard | Q31: Hard
A32: original_3_current | B32: original_progression_3_current | C32: FALSE | D32: FALSE | E32: Original Progression 3 | F32: Original Order | G32: tutorial_level.json | H32: procedular_reference_large_021.json | I32: procedular_reference_large_022.json | J32: procedular_reference_large_023.json | K32: procedular_reference_large_024.json | L32: procedular_reference_large_025.json | M32: procedular_reference_large_026.json | N32: procedular_reference_large_027.json | O32: procedular_reference_large_028.json | P32: procedular_reference_large_029.json | Q32: procedular_reference_large_030.json | R32: =SPARKLINE({IFERROR(VLOOKUP(H32,'Level Catalog'!A:E,5,FALSE),0),IFERROR(VLOOKUP(I32,'Level Catalog'!A:E,5,FALSE),0),IFERROR(VLOOKUP(J32,'Level Catalog'!A:E,5,FALSE),0),IFERROR(VLOOKUP(K32,'Level Catalog'!A:E,5,FALSE),0),IFERROR(VLOOKUP(L32,'Level Catalog'!A:E,5,FALSE),0),IFERROR(VLOOKUP(M32,'Level Catalog'!A:E,5,FALSE),0),IFERROR(VLOOKUP(N32,'Level Catalog'!A:E,5,FALSE),0),IFERROR(VLOOKUP(O32,'Level Catalog'!A:E,5,FALSE),0),IFERROR(VLOOKUP(P32,'Level Catalog'!A:E,5,FALSE),0),IFERROR(VLOOKUP(Q32,'Level Catalog'!A:E,5,FALSE),0)},{"charttype","line";"linewidth",2;"empty","zero"})
F33: Screens | G33: lvl_109_tutorial_level.png | H33: procedular_reference_large_021.png | I33: procedular_reference_large_022.png | J33: procedular_reference_large_023.png | K33: procedular_reference_large_024.png | L33: procedular_reference_large_025.png | M33: procedular_reference_large_026.png | N33: procedular_reference_large_027.png | O33: procedular_reference_large_028.png | P33: procedular_reference_large_029.png | Q33: procedular_reference_large_030.png
F34: Difficulty | G34: Easy | H34: Hard | I34: Hard | J34: Hard | K34: Hard | L34: Hard | M34: Hard | N34: Hard | O34: Hard | P34: Hard | Q34: Hard
A35: original_3_rotate_1 | B35: original_progression_3_rotate_1 | C35: FALSE | D35: FALSE | E35: Original Progression 3 | F35: Rotate +1 | G35: tutorial_level.json | H35: procedular_reference_large_022.json | I35: procedular_reference_large_023.json | J35: procedular_reference_large_024.json | K35: procedular_reference_large_025.json | L35: procedular_reference_large_026.json | M35: procedular_reference_large_027.json | N35: procedular_reference_large_028.json | O35: procedular_reference_large_029.json | P35: procedular_reference_large_030.json | Q35: procedular_reference_large_021.json | R35: =SPARKLINE({IFERROR(VLOOKUP(H35,'Level Catalog'!A:E,5,FALSE),0),IFERROR(VLOOKUP(I35,'Level Catalog'!A:E,5,FALSE),0),IFERROR(VLOOKUP(J35,'Level Catalog'!A:E,5,FALSE),0),IFERROR(VLOOKUP(K35,'Level Catalog'!A:E,5,FALSE),0),IFERROR(VLOOKUP(L35,'Level Catalog'!A:E,5,FALSE),0),IFERROR(VLOOKUP(M35,'Level Catalog'!A:E,5,FALSE),0),IFERROR(VLOOKUP(N35,'Level Catalog'!A:E,5,FALSE),0),IFERROR(VLOOKUP(O35,'Level Catalog'!A:E,5,FALSE),0),IFERROR(VLOOKUP(P35,'Level Catalog'!A:E,5,FALSE),0),IFERROR(VLOOKUP(Q35,'Level Catalog'!A:E,5,FALSE),0)},{"charttype","line";"linewidth",2;"empty","zero"})
F36: Screens | G36: lvl_109_tutorial_level.png | H36: procedular_reference_large_022.png | I36: procedular_reference_large_023.png | J36: procedular_reference_large_024.png | K36: procedular_reference_large_025.png | L36: procedular_reference_large_026.png | M36: procedular_reference_large_027.png | N36: procedular_reference_large_028.png | O36: procedular_reference_large_029.png | P36: procedular_reference_large_030.png | Q36: procedular_reference_large_021.png
F37: Difficulty | G37: Easy | H37: Hard | I37: Hard | J37: Hard | K37: Hard | L37: Hard | M37: Hard | N37: Hard | O37: Hard | P37: Hard | Q37: Hard
A38: original_4_current | B38: original_progression_4_current | C38: FALSE | D38: FALSE | E38: Original Progression 4 | F38: Original Order | G38: tutorial_level.json | H38: procedural_2_level_1_new_20260322234743.json | I38: procedular_reference_large_032.json | J38: procedular_reference_large_033.json | K38: procedular_reference_large_034.json | L38: procedular_reference_large_035.json | M38: procedular_reference_large_036.json | N38: procedular_reference_large_037.json | O38: procedular_reference_large_038.json | P38: procedular_reference_large_039.json | Q38: procedular_reference_large_040.json | R38: =SPARKLINE({IFERROR(VLOOKUP(H38,'Level Catalog'!A:E,5,FALSE),0),IFERROR(VLOOKUP(I38,'Level Catalog'!A:E,5,FALSE),0),IFERROR(VLOOKUP(J38,'Level Catalog'!A:E,5,FALSE),0),IFERROR(VLOOKUP(K38,'Level Catalog'!A:E,5,FALSE),0),IFERROR(VLOOKUP(L38,'Level Catalog'!A:E,5,FALSE),0),IFERROR(VLOOKUP(M38,'Level Catalog'!A:E,5,FALSE),0),IFERROR(VLOOKUP(N38,'Level Catalog'!A:E,5,FALSE),0),IFERROR(VLOOKUP(O38,'Level Catalog'!A:E,5,FALSE),0),IFERROR(VLOOKUP(P38,'Level Catalog'!A:E,5,FALSE),0),IFERROR(VLOOKUP(Q38,'Level Catalog'!A:E,5,FALSE),0)},{"charttype","line";"linewidth",2;"empty","zero"})
F39: Screens | G39: lvl_109_tutorial_level.png | H39: procedural_2_level_1_new_20260322234743.png | I39: procedular_reference_large_032.png | J39: procedular_reference_large_033.png | K39: procedular_reference_large_034.png | L39: procedular_reference_large_035.png | M39: procedular_reference_large_036.png | N39: procedular_reference_large_037.png | O39: procedular_reference_large_038.png | P39: procedular_reference_large_039.png | Q39: procedular_reference_large_040.png
F40: Difficulty | G40: Easy | H40: Hard | I40: Hard | J40: Hard | K40: Hard | L40: Hard | M40: Hard | N40: Hard | O40: Hard | P40: Hard | Q40: Hard
...

Sheet Level Renames
A1: Occurrence ID | B1: Progression | C1: Position | D1: Ordinal | E1: Screenshot | F1: Current Name | G1: Target Name | H1: Preview Label | I1: Code File | J1: Level Path | K1: Screenshot File | L1: Screenshot Path | M1: Planned File | N1: Rename Pending | O1: Apply Status | P1: Notes
A2: progressionA:01 | B2: Progression A | C2: 1 | D2: 01 | F2: progression1 level1 | H2: 01 · progression1 level1 | I2: progression1_level1.json | J2: /Users/victoria.serrano/Library/CloudStorage/SynologyDrive-back1/misScripts/minigame_locally/levels/progression1_level1.json | K2: progression1_level1.png | L2: /sessions/bold-affectionate-fermi/mnt/minigame_locally/levels/screenshots/progression1_level1.png | M2: progression1_level1.json | N2: FALSE
A3: progressionA:02 | B3: Progression A | C3: 2 | D3: 02 | F3: progresion1 level2 | H3: 02 · progresion1 level2 | I3: progresion1_level2.json | J3: /Users/victoria.serrano/Library/CloudStorage/SynologyDrive-back1/misScripts/minigame_locally/levels/progresion1_level2.json | K3: progresion1_level2.png | L3: /sessions/bold-affectionate-fermi/mnt/minigame_locally/levels/screenshots/progresion1_level2.png | M3: progresion1_level2.json | N3: FALSE
A4: progressionA:03 | B4: Progression A | C4: 3 | D4: 03 | F4: progression1 level3 | H4: 03 · progression1 level3 | I4: progression1_level3.json | J4: /Users/victoria.serrano/Library/CloudStorage/SynologyDrive-back1/misScripts/minigame_locally/levels/progression1_level3.json | K4: progression1_level3.png | L4: /sessions/bold-affectionate-fermi/mnt/minigame_locally/levels/screenshots/progression1_level3.png | M4: progression1_level3.json | N4: FALSE
A5: progressionA:04 | B5: Progression A | C5: 4 | D5: 04 | F5: progression1 level4 | H5: 04 · progression1 level4 | I5: progression1_level4.json | J5: /Users/victoria.serrano/Library/CloudStorage/SynologyDrive-back1/misScripts/minigame_locally/levels/progression1_level4.json | K5: progression1_level4.png | L5: /sessions/bold-affectionate-fermi/mnt/minigame_locally/levels/screenshots/progression1_level4.png | M5: progression1_level4.json | N5: FALSE
A6: progressionA:05 | B6: Progression A | C6: 5 | D6: 05 | F6: progression1 level5 | H6: 05 · progression1 level5 | I6: progression1_level5.json | J6: /Users/victoria.serrano/Library/CloudStorage/SynologyDrive-back1/misScripts/minigame_locally/levels/progression1_level5.json | K6: progression1_level5.png | L6: /sessions/bold-affectionate-fermi/mnt/minigame_locally/levels/screenshots/progression1_level5.png | M6: progression1_level5.json | N6: FALSE
A7: progressionA:06 | B7: Progression A | C7: 6 | D7: 06 | F7: progresion1 level6 | H7: 06 · progresion1 level6 | I7: progresion1_level6.json | J7: /Users/victoria.serrano/Library/CloudStorage/SynologyDrive-back1/misScripts/minigame_locally/levels/progresion1_level6.json | K7: progresion1_level6.png | L7: /sessions/bold-affectionate-fermi/mnt/minigame_locally/levels/screenshots/progresion1_level6.png | M7: progresion1_level6.json | N7: FALSE
A8: progressionA:07 | B8: Progression A | C8: 7 | D8: 07 | F8: progression1 level7 v2 | H8: 07 · progression1 level7 v2 | I8: progression1_level7_v2.json | J8: /Users/victoria.serrano/Library/CloudStorage/SynologyDrive-back1/misScripts/minigame_locally/levels/progression1_level7_v2.json | K8: progression1_level7_v2.png | L8: /sessions/bold-affectionate-fermi/mnt/minigame_locally/levels/screenshots/progression1_level7_v2.png | M8: progression1_level7_v2.json | N8: FALSE
A9: progressionA:08 | B9: Progression A | C9: 8 | D9: 08 | F9: progression1 level8 | H9: 08 · progression1 level8 | I9: progression1_level8.json | J9: /Users/victoria.serrano/Library/CloudStorage/SynologyDrive-back1/misScripts/minigame_locally/levels/progression1_level8.json | K9: progression1_level8.png | L9: /sessions/bold-affectionate-fermi/mnt/minigame_locally/levels/screenshots/progression1_level8.png | M9: progression1_level8.json | N9: FALSE
A10: progressionA:09 | B10: Progression A | C10: 9 | D10: 09 | F10: progression1 level9 | H10: 09 · progression1 level9 | I10: progression1_level9.json | J10: /Users/victoria.serrano/Library/CloudStorage/SynologyDrive-back1/misScripts/minigame_locally/levels/progression1_level9.json | K10: progression1_level9.png | L10: /sessions/bold-affectionate-fermi/mnt/minigame_locally/levels/screenshots/progression1_level9.png | M10: progression1_level9.json | N10: FALSE
A11: progressionA:10 | B11: Progression A | C11: 10 | D11: 10 | F11: progression1 level10 | H11: 10 · progression1 level10 | I11: progression1_level10.json | J11: /Users/victoria.serrano/Library/CloudStorage/SynologyDrive-back1/misScripts/minigame_locally/levels/progression1_level10.json | K11: progression1_level10.png | L11: /sessions/bold-affectionate-fermi/mnt/minigame_locally/levels/screenshots/progression1_level10.png | M11: progression1_level10.json | N11: FALSE
A12: progressionB:01 | B12: Progression B | C12: 1 | D12: 01 | F12: progresion2 level1 | H12: 01 · progresion2 level1 | I12: progresion2_level1.json | J12: /Users/victoria.serrano/Library/CloudStorage/SynologyDrive-back1/misScripts/minigame_locally/levels/progresion2_level1.json | K12: progresion2_level1.png | L12: /sessions/bold-affectionate-fermi/mnt/minigame_locally/levels/screenshots/progresion2_level1.png | M12: progresion2_level1.json | N12: FALSE
A13: progressionB:02 | B13: Progression B | C13: 2 | D13: 02 | F13: progresion2 level2 | H13: 02 · progresion2 level2 | I13: progresion2_level2.json | J13: /Users/victoria.serrano/Library/CloudStorage/SynologyDrive-back1/misScripts/minigame_locally/levels/progresion2_level2.json | K13: progresion2_level2.png | L13: /sessions/bold-affectionate-fermi/mnt/minigame_locally/levels/screenshots/progresion2_level2.png | M13: progresion2_level2.json | N13: FALSE
... A131: progression_13:10 | B131: Procedural 10 | C131: 10 | D131: 10 | F131: procedular reference large 102 | H131: 10 · procedular reference large 102 | I131: procedular_reference_large_102.json | J131: /Users/victoria.serrano/Library/CloudStorage/SynologyDrive-back1/misScripts/minigame_locally/levels/procedular_reference_large_102.json | K131: procedular_reference_large_102.png | L131: /sessions/bold-affectionate-fermi/mnt/minigame_locally/levels/screenshots/procedular_reference_large_102.png | M131: procedular_reference_large_102.json | N131: FALSE

Sheet Level Catalog
A1: File | B1: Display Name | C1: Source Progression | D1: Difficulty | E1: Difficulty Score | F1: Board | G1: Pairs | H1: Blockers | I1: Moves | J1: Status | K1: Screenshot | L1: Saved Path | M1: Grid Compliance
A2: tutorial_level.json | B2: tutorial | C2: Progression A | D2: Easy | E2: 1.083 | F2: 6x6 | G2: 3 | H2: 3 | I2: 8 | J2: OK | K2: lvl_109_tutorial_level.png | L2: /Users/victoria.serrano/Library/CloudStorage/SynologyDrive-back1/misScripts/minigame_locally/levels/tutorial_level.json | M2: OK
A3: progression1_level1.json | B3: progression1 level1 | C3: Progression A | D3: Easy | E3: 1.064 | F3: 5x5 | G3: 4 | H3: 1 | I3: 6 | J3: OK | K3: progression1_level1.png | L3: /Users/victoria.serrano/Library/CloudStorage/SynologyDrive-back1/misScripts/minigame_locally/levels/progression1_level1.json | M3: OK
A4: progresion1_level2.json | B4: progresion1 level2 | C4: Progression A | D4: Easy | E4: 1.053 | F4: 5x5 | G4: 3 | H4: 0 | I4: 5 | J4: OK | K4: progresion1_level2.png | L4: /Users/victoria.serrano/Library/CloudStorage/SynologyDrive-back1/misScripts/minigame_locally/levels/progresion1_level2.json | M4: OK
A5: progression1_level3.json | B5: progression1 level3 | C5: Progression A | D5: Medium | E5: 2.053 | F5: 4x4 | G5: 3 | H5: 1 | I5: 5 | J5: OK | K5: progression1_level3.png | L5: /Users/victoria.serrano/Library/CloudStorage/SynologyDrive-back1/misScripts/minigame_locally/levels/progression1_level3.json | M5: OK
A6: progression1_level4.json | B6: progression1 level4 | C6: Progression A | D6: Easy | E6: 1.075 | F6: 5x5 | G6: 5 | H6: 3 | I6: 7 | J6: OK | K6: progression1_level4.png | L6: /Users/victoria.serrano/Library/CloudStorage/SynologyDrive-back1/misScripts/minigame_locally/levels/progression1_level4.json | M6: OK
A7: progression1_level5.json | B7: progression1 level5 | C7: Progression A | D7: Easy | E7: 1.053 | F7: 4x4 | G7: 3 | H7: 0 | I7: 5 | J7: OK | K7: progression1_level5.png | L7: /Users/victoria.serrano/Library/CloudStorage/SynologyDrive-back1/misScripts/minigame_locally/levels/progression1_level5.json | M7: OK
A8: progresion1_level6.json | B8: progresion1 level6 | C8: Progression A | D8: Medium | E8: 2.065 | F8: 6x6 | G8: 4 | H8: 5 | I8: 6 | J8: OK | K8: progresion1_level6.png | L8: /Users/victoria.serrano/Library/CloudStorage/SynologyDrive-back1/misScripts/minigame_locally/levels/progresion1_level6.json | M8: OK
A9: progression1_level7_v2.json | B9: progression1 level7 v2 | C9: Progression A | D9: Hard | E9: 3.087 | F9: 7x7 | G9: 6 | H9: 6 | I9: 8 | J9: OK | K9: progression1_level7_v2.png | L9: /Users/victoria.serrano/Library/CloudStorage/SynologyDrive-back1/misScripts/minigame_locally/levels/progression1_level7_v2.json | M9: OK
A10: progression1_level8.json | B10: progression1 level8 | C10: Progression A | D10: Easy | E10: 1.074 | F10: 6x6 | G10: 3 | H10: 6 | I10: 7 | J10: OK | K10: progression1_level8.png | L10: /Users/victoria.serrano/Library/CloudStorage/SynologyDrive-back1/misScripts/minigame_locally/levels/progression1_level8.json | M10: OK
A11: progression1_level9.json | B11: progression1 level9 | C11: Progression A | D11: Medium | E11: 2.074 | F11: 5x5 | G11: 4 | H11: 2 | I11: 7 | J11: OK | K11: progression1_level9.png | L11: /Users/victoria.serrano/Library/CloudStorage/SynologyDrive-back1/misScripts/minigame_locally/levels/progression1_level9.json | M11: OK
A12: progression1_level10.json | B12: progression1 level10 | C12: Progression A | D12: Hard | E12: 3.065 | F12: 6x7 | G12: 4 | H12: 7 | I12: 6 | J12: OK | K12: progression1_level10.png | L12: /Users/victoria.serrano/Library/CloudStorage/SynologyDrive-back1/misScripts/minigame_locally/levels/progression1_level10.json | M12: OK
A13: progresion2_level1.json | B13: progresion2 level1 | C13: Progression B | D13: Easy | E13: 1.053 | F13: 5x5 | G13: 2 | H13: 7 | I13: 5 | J13: OK | K13: progresion2_level1.png | L13: /Users/victoria.serrano/Library/CloudStorage/SynologyDrive-back1/misScripts/minigame_locally/levels/progresion2_level1.json | M13: OK
... A132: procedular_reference_large_102.json | B132: procedular reference large 102 | C132: Procedural 10 | D132: Hard | E132: 3.133 | F132: 7x7 | G132: 3 | H132: 0 | I132: 13 | J132: OK | K132: procedular_reference_large_102.png | L132: /Users/victoria.serrano/Library/CloudStorage/SynologyDrive-back1/misScripts/minigame_locally/levels/procedular_reference_large_102.json | M132: OK

Sheet Level Manager state
A1: row_type | B1: saved_at | C1: item_id | D1: progression_key | E1: progression_label | F1: slot | G1: level_file | H1: level_name | I1: difficulty | J1: board | K1: pairs | L1: blockers | M1: moves | N1: status | O1: changed | P1: notes | Q1: source_path | R1: saved_path | S1: Grid Compliance
A2: slot | D2: progressionA | E2: Progression A | F2: 0 | G2: tutorial_level.json | H2: tutorial | I2: EASY | J2: 6x6 | K2: 3 | L2: 3 | M2: 8 | N2: OK | O2: Yes | P2: Tutorial slot | Q2: minigame_locally/levels/tutorial_level.json | R2: /Users/victoria.serrano/Library/CloudStorage/SynologyDrive-back1/misScripts/minigame_locally/levels/tutorial_level.json | S2: OK
A3: slot | D3: progressionA | E3: Progression A | F3: 1 | G3: progression1_level1.json | H3: progression1 level1 | I3: EASY | J3: 5x5 | K3: 4 | L3: 1 | M3: 6 | N3: OK | O3: Yes | Q3: minigame_locally/levels/progression1_level1.json | R3: /Users/victoria.serrano/Library/CloudStorage/SynologyDrive-back1/misScripts/minigame_locally/levels/progression1_level1.json | S3: OK
A4: slot | D4: progressionA | E4: Progression A | F4: 2 | G4: progresion1_level2.json | H4: progresion1 level2 | I4: EASY | J4: 5x5 | K4: 3 | L4: 0 | M4: 5 | N4: OK | O4: Yes | Q4: minigame_locally/levels/progresion1_level2.json | R4: /Users/victoria.serrano/Library/CloudStorage/SynologyDrive-back1/misScripts/minigame_locally/levels/progresion1_level2.json | S4: OK
A5: slot | D5: progressionA | E5: Progression A | F5: 3 | G5: progression1_level3.json | H5: progression1 level3 | I5: MEDIUM | J5: 4x4 | K5: 3 | L5: 1 | M5: 5 | N5: OK | O5: Yes | Q5: minigame_locally/levels/progression1_level3.json | R5: /Users/victoria.serrano/Library/CloudStorage/SynologyDrive-back1/misScripts/minigame_locally/levels/progression1_level3.json | S5: OK
A6: slot | D6: progressionA | E6: Progression A | F6: 4 | G6: progression1_level4.json | H6: progression1 level4 | I6: EASY | J6: 5x5 | K6: 5 | L6: 3 | M6: 7 | N6: OK | O6: Yes | Q6: minigame_locally/levels/progression1_level4.json | R6: /Users/victoria.serrano/Library/CloudStorage/SynologyDrive-back1/misScripts/minigame_locally/levels/progression1_level4.json | S6: OK
A7: slot | D7: progressionA | E7: Progression A | F7: 5 | G7: progression1_level5.json | H7: progression1 level5 | I7: EASY | J7: 4x4 | K7: 3 | L7: 0 | M7: 5 | N7: OK | O7: Yes | Q7: minigame_locally/levels/progression1_level5.json | R7: /Users/victoria.serrano/Library/CloudStorage/SynologyDrive-back1/misScripts/minigame_locally/levels/progression1_level5.json | S7: OK
A8: slot | D8: progressionA | E8: Progression A | F8: 6 | G8: progresion1_level6.json | H8: progresion1 level6 | I8: MEDIUM | J8: 6x6 | K8: 4 | L8: 5 | M8: 6 | N8: OK | O8: Yes | Q8: minigame_locally/levels/progresion1_level6.json | R8: /Users/victoria.serrano/Library/CloudStorage/SynologyDrive-back1/misScripts/minigame_locally/levels/progresion1_level6.json | S8: OK
A9: slot | D9: progressionA | E9: Progression A | F9: 7 | G9: progression1_level7_v2.json | H9: progression1 level7 v2 | I9: HARD | J9: 7x7 | K9: 6 | L9: 6 | M9: 8 | N9: OK | O9: Yes | Q9: minigame_locally/levels/progression1_level7_v2.json | R9: /Users/victoria.serrano/Library/CloudStorage/SynologyDrive-back1/misScripts/minigame_locally/levels/progression1_level7_v2.json | S9: OK
A10: slot | D10: progressionA | E10: Progression A | F10: 8 | G10: progression1_level8.json | H10: progression1 level8 | I10: EASY | J10: 6x6 | K10: 3 | L10: 6 | M10: 7 | N10: OK | O10: Yes | Q10: minigame_locally/levels/progression1_level8.json | R10: /Users/victoria.serrano/Library/CloudStorage/SynologyDrive-back1/misScripts/minigame_locally/levels/progression1_level8.json | S10: OK
A11: slot | D11: progressionA | E11: Progression A | F11: 9 | G11: progression1_level9.json | H11: progression1 level9 | I11: MEDIUM | J11: 5x5 | K11: 4 | L11: 2 | M11: 7 | N11: OK | O11: Yes | Q11: minigame_locally/levels/progression1_level9.json | R11: /Users/victoria.serrano/Library/CloudStorage/SynologyDrive-back1/misScripts/minigame_locally/levels/progression1_level9.json | S11: OK
A12: slot | D12: progressionA | E12: Progression A | F12: 10 | G12: progression1_level10.json | H12: progression1 level10 | I12: HARD | J12: 6x7 | K12: 4 | L12: 7 | M12: 6 | N12: OK | O12: Yes | Q12: minigame_locally/levels/progression1_level10.json | R12: /Users/victoria.serrano/Library/CloudStorage/SynologyDrive-back1/misScripts/minigame_locally/levels/progression1_level10.json | S12: OK
A13: slot | D13: progressionB | E13: Progression B | F13: 0 | G13: tutorial_level.json | H13: tutorial | I13: EASY | J13: 6x6 | K13: 3 | L13: 3 | M13: 8 | N13: OK | O13: Yes | P13: Tutorial slot | Q13: minigame_locally/levels/tutorial_level.json | R13: /Users/victoria.serrano/Library/CloudStorage/SynologyDrive-back1/misScripts/minigame_locally/levels/tutorial_level.json | S13: OK
A14: slot | D14: progressionB | E14: Progression B | F14: 1 | G14: progresion2_level1.json | H14: progresion2 level1 | I14: EASY | J14: 5x5 | K14: 2 | L14: 7 | M14: 5 | N14: OK | O14: Yes | Q14: minigame_locally/levels/progresion2_level1.json | R14: /Users/victoria.serrano/Library/CloudStorage/SynologyDrive-back1/misScripts/minigame_locally/levels/progresion2_level1.json | S14: OK
A15: slot | D15: progressionB | E15: Progression B | F15: 2 | G15: progresion2_level2.json | H15: progresion2 level2 | I15: EASY | J15: 4x4 | K15: 3 | L15: 2 | M15: 6 | N15: OK | O15: Yes | Q15: minigame_locally/levels/progresion2_level2.json | R15: /Users/victoria.serrano/Library/CloudStorage/SynologyDrive-back1/misScripts/minigame_locally/levels/progresion2_level2.json | S15: OK
A16: slot | D16: progressionB | E16: Progression B | F16: 3 | G16: progresion2_level3.json | H16: progresion2 level3 | I16: MEDIUM | J16: 6x6 | K16: 4 | L16: 6 | M16: 6 | N16: OK | O16: Yes | Q16: minigame_locally/levels/progresion2_level3.json | R16: /Users/victoria.serrano/Library/CloudStorage/SynologyDrive-back1/misScripts/minigame_locally/levels/progresion2_level3.json | S16: OK
A17: slot | D17: progressionB | E17: Progression B | F17: 4 | G17: progresion2_level4.json | H17: progresion2 level4 | I17: HARD | J17: 7x7 | K17: 4 | L17: 3 | M17: 6 | N17: INVALID | O17: Yes | Q17: minigame_locally/levels/progresion2_level4.json | R17: /Users/victoria.serrano/Library/CloudStorage/SynologyDrive-back1/misScripts/minigame_locally/levels/progresion2_level4.json | S17: OK
A18: slot | D18: progressionB | E18: Progression B | F18: 5 | G18: progresion2_level5.json | H18: progresion2 level5 | I18: EASY | J18: 7x7 | K18: 4 | L18: 10 | M18: 5 | N18: OK | O18: Yes | Q18: minigame_locally/levels/progresion2_level5.json | R18: /Users/victoria.serrano/Library/CloudStorage/SynologyDrive-back1/misScripts/minigame_locally/levels/progresion2_level5.json | S18: OK
A19: slot | D19: progressionB | E19: Progression B | F19: 6 | G19: progresion2_level6.json | H19: progresion2 level6 | I19: MEDIUM | J19: 6x6 | K19: 3 | L19: 4 | M19: 5 | N19: OK | O19: Yes | Q19: minigame_locally/levels/progresion2_level6.json | R19: /Users/victoria.serrano/Library/CloudStorage/SynologyDrive-back1/misScripts/minigame_locally/levels/progresion2_level6.json | S19: OK
A20: slot | D20: progressionB | E20: Progression B | F20: 7 | G20: progresion2_level7.json | H20: progresion2 level7 | I20: HARD | J20: 8x9 | K20: 8 | L20: 6 | M20: 9 | N20: OK | O20: Yes | Q20: minigame_locally/levels/progresion2_level7.json | R20: /Users/victoria.serrano/Library/CloudStorage/SynologyDrive-back1/misScripts/minigame_locally/levels/progresion2_level7.json | S20: OVERSIZED
A21: slot | D21: progressionB | E21: Progression B | F21: 8 | G21: progresion2_level8.json | H21: progresion2 level8 | I21: EASY | J21: 8x8 | K21: 7 | L21: 1 | M21: 0 | N21: INVALID | O21: Yes | Q21: minigame_locally/levels/progresion2_level8.json | R21: /Users/victoria.serrano/Library/CloudStorage/SynologyDrive-back1/misScripts/minigame_locally/levels/progresion2_level8.json | S21: OVERSIZED
A22: slot | D22: progressionB | E22: Progression B | F22: 9 | G22: progresion2_level9.json | H22: progresion2 level9 | I22: MEDIUM | J22: 8x8 | K22: 6 | L22: 7 | M22: 7 | N22: OK | O22: Yes | Q22: minigame_locally/levels/progresion2_level9.json | R22: /Users/victoria.serrano/Library/CloudStorage/SynologyDrive-back1/misScripts/minigame_locally/levels/progresion2_level9.json | S22: OVERSIZED
A23: slot | D23: progressionB | E23: Progression B | F23: 10 | G23: progresion2_level10.json | H23: progresion2 level10 | I23: HARD | J23: 8x8 | K23: 5 | L23: 7 | M23: 6 | N23: INVALID | O23: Yes | Q23: minigame_locally/levels/progresion2_level10.json | R23: /Users/victoria.serrano/Library/CloudStorage/SynologyDrive-back1/misScripts/minigame_locally/levels/progresion2_level10.json | S23: OVERSIZED
A24: slot | D24: progressionC | E24: Progression C | F24: 0 | G24: tutorial_level.json | H24: tutorial | I24: EASY | J24: 6x6 | K24: 3 | L24: 3 | M24: 8 | N24: OK | O24: Yes | P24: Tutorial slot | Q24: minigame_locally/levels/tutorial_level.json | R24: /Users/victoria.serrano/Library/CloudStorage/SynologyDrive-back1/misScripts/minigame_locally/levels/tutorial_level.json | S24: OK
A25: slot | D25: progressionC | E25: Progression C | F25: 1 | G25: progression3_level1_v2.json | H25: progression3 level1 v2 | I25: EASY | J25: 5x5 | K25: 6 | L25: 3 | M25: 8 | N25: OK | O25: Yes | Q25: minigame_locally/levels/progression3_level1_v2.json | R25: /Users/victoria.serrano/Library/CloudStorage/SynologyDrive-back1/misScripts/minigame_locally/levels/progression3_level1_v2.json | S25: OK
A26: slot | D26: progressionC | E26: Progression C | F26: 2 | G26: progression_3_level_2_v2.json | H26: progression 3 level 2 v2 | I26: EASY | J26: 6x6 | K26: 6 | L26: 10 | M26: 8 | N26: OK | O26: Yes | Q26: minigame_locally/levels/progression_3_level_2_v2.json | R26: /Users/victoria.serrano/Library/CloudStorage/SynologyDrive-back1/misScripts/minigame_locally/levels/progression_3_level_2_v2.json | S26: OK
A27: slot | D27: progressionC | E27: Progression C | F27: 3 | G27: progression_3_level3.json | H27: progression 3 level3 | I27: MEDIUM | J27: 8x7 | K27: 3 | L27: 9 | M27: 6 | N27: OK | O27: Yes | Q27: minigame_locally/levels/progression_3_level3.json | R27: /Users/victoria.serrano/Library/CloudStorage/SynologyDrive-back1/misScripts/minigame_locally/levels/progression_3_level3.json | S27: OK
A28: slot | D28: progressionC | E28: Progression C | F28: 4 | G28: progression_3_level4.json | H28: progression 3 level4 | I28: EASY | J28: 7x7 | K28: 4 | L28: 10 | M28: 7 | N28: OK | O28: Yes | Q28: minigame_locally/levels/progression_3_level4.json | R28: /Users/victoria.serrano/Library/CloudStorage/SynologyDrive-back1/misScripts/minigame_locally/levels/progression_3_level4.json | S28: OK
A29: slot | D29: progressionC | E29: Progression C | F29: 5 | G29: progression_3_level5.json | H29: progression 3 level5 | I29: MEDIUM | J29: 6x6 | K29: 4 | L29: 4 | M29: 8 | N29: OK | O29: Yes | Q29: minigame_locally/levels/progression_3_level5.json | R29: /Users/victoria.serrano/Library/CloudStorage/SynologyDrive-back1/misScripts/minigame_locally/levels/progression_3_level5.json | S29: OK
A30: slot | D30: progressionC | E30: Progression C | F30: 6 | G30: progression_3_level6.json | H30: progression 3 level6 | I30: EASY | J30: 8x8 | K30: 5 | L30: 4 | M30: 9 | N30: INVALID | O30: Yes | Q30: minigame_locally/levels/progression_3_level6.json | R30: /Users/victoria.serrano/Library/CloudStorage/SynologyDrive-back1/misScripts/minigame_locally/levels/progression_3_level6.json | S30: OVERSIZED
A31: slot | D31: progressionC | E31: Progression C | F31: 7 | G31: progression_3_level7_v2.json | H31: progression 3 level7 v2 | I31: MEDIUM | J31: 8x8 | K31: 6 | L31: 1 | M31: 6 | N31: INVALID | O31: Yes | Q31: minigame_locally/levels/progression_3_level7_v2.json | R31: /Users/victoria.serrano/Library/CloudStorage/SynologyDrive-back1/misScripts/minigame_locally/levels/progression_3_level7_v2.json | S31: OVERSIZED
A32: slot | D32: progressionC | E32: Progression C | F32: 8 | G32: progression_3_level_8_v2.json | H32: progression 3 level 8 v2 | I32: EASY | J32: 8x9 | K32: 6 | L32: 11 | M32: 8 | N32: INVALID | O32: Yes | Q32: minigame_locally/levels/progression_3_level_8_v2.json | R32: /Users/victoria.serrano/Library/CloudStorage/SynologyDrive-back1/misScripts/minigame_locally/levels/progression_3_level_8_v2.json | S32: OVERSIZED
A33: slot | D33: progressionC | E33: Progression C | F33: 9 | G33: progression_3_level9_v2.json | H33: progression 3 level9 v2 | I33: MEDIUM | J33: 9x9 | K33: 9 | L33: 12 | M33: 6 | N33: OK | O33: Yes | Q33: minigame_locally/levels/progression_3_level9_v2.json | R33: /Users/victoria.serrano/Library/CloudStorage/SynologyDrive-back1/misScripts/minigame_locally/levels/progression_3_level9_v2.json | S33: OVERSIZED
A34: slot | D34: progressionC | E34: Progression C | F34: 10 | G34: progression_3_level10_v2.json | H34: progression 3 level10 v2 | I34: HARD | J34: 9x9 | K34: 8 | L34: 5 | M34: 9 | N34: OK | O34: Yes | Q34: minigame_locally/levels/progression_3_level10_v2.json | R34: /Users/victoria.serrano/Library/CloudStorage/SynologyDrive-back1/misScripts/minigame_locally/levels/progression_3_level10_v2.json | S34: OVERSIZED
A35: slot | D35: progression_4 | E35: Procedural 1 | F35: 0 | G35: tutorial_level.json | H35: tutorial | I35: EASY | J35: 6x6 | K35: 3 | L35: 3 | M35: 8 | N35: OK | O35: Yes | P35: Tutorial slot | Q35: minigame_locally/levels/tutorial_level.json | R35: /Users/victoria.serrano/Library/CloudStorage/SynologyDrive-back1/misScripts/minigame_locally/levels/tutorial_level.json | S35: OK
A36: slot | D36: progression_4 | E36: Procedural 1 | F36: 1 | G36: slot2_1.json | H36: slot2 1 | I36: EASY | J36: 7x7 | K36: 5 | L36: 8 | M36: 7 | N36: OK | O36: Yes | Q36: minigame_locally/levels/slot2_1.json | R36: /Users/victoria.serrano/Library/CloudStorage/SynologyDrive-back1/misScripts/minigame_locally/levels/slot2_1.json | S36: OK
A37: slot | D37: progression_4 | E37: Procedural 1 | F37: 2 | G37: slot2_2.json | H37: slot2 2 | I37: HARD | J37: 8x8 | K37: 6 | L37: 8 | M37: 8 | N37: OK | O37: Yes | Q37: minigame_locally/levels/slot2_2.json | R37: /Users/victoria.serrano/Library/CloudStorage/SynologyDrive-back1/misScripts/minigame_locally/levels/slot2_2.json | S37: OVERSIZED
A38: slot | D38: progression_4 | E38: Procedural 1 | F38: 3 | G38: slot2_3.json | H38: slot2 3 | I38: HARD | J38: 7x7 | K38: 4 | L38: 6 | M38: 9 | N38: OK | O38: Yes | Q38: minigame_locally/levels/slot2_3.json | R38: /Users/victoria.serrano/Library/CloudStorage/SynologyDrive-back1/misScripts/minigame_locally/levels/slot2_3.json | S38: OK
A39: slot | D39: progression_4 | E39: Procedural 1 | F39: 4 | G39: slot2_4.json | H39: slot2 4 | I39: HARD | J39: 7x7 | K39: 5 | L39: 8 | M39: 8 | N39: OK | O39: Yes | Q39: minigame_locally/levels/slot2_4.json | R39: /Users/victoria.serrano/Library/CloudStorage/SynologyDrive-back1/misScripts/minigame_locally/levels/slot2_4.json | S39: OK
A40: slot | D40: progression_4 | E40: Procedural 1 | F40: 5 | G40: procedular_reference_large_005.json | H40: procedular reference large 005 | I40: HARD | J40: 7x7 | K40: 3 | L40: 9 | M40: 14 | N40: OK | O40: Yes | Q40: minigame_locally/levels/procedular_reference_large_005.json | R40: /Users/victoria.serrano/Library/CloudStorage/SynologyDrive-back1/misScripts/minigame_locally/levels/procedular_reference_large_005.json | S40: OK
...
